Traceback (most recent call last):
  File "/home/runner/.local/lib/python3.10/site-packages/jupyter_cache/executors/utils.py", line 58, in single_nb_execution
    executenb(
  File "/home/runner/.local/lib/python3.10/site-packages/nbclient/client.py", line 1204, in execute
    return NotebookClient(nb=nb, resources=resources, km=km, **kwargs).execute()
  File "/home/runner/.local/lib/python3.10/site-packages/nbclient/util.py", line 84, in wrapped
    return just_run(coro(*args, **kwargs))
  File "/home/runner/.local/lib/python3.10/site-packages/nbclient/util.py", line 62, in just_run
    return loop.run_until_complete(coro)
  File "/usr/lib/python3.10/asyncio/base_events.py", line 646, in run_until_complete
    return future.result()
  File "/home/runner/.local/lib/python3.10/site-packages/nbclient/client.py", line 663, in async_execute
    await self.async_execute_cell(
  File "/home/runner/.local/lib/python3.10/site-packages/nbclient/client.py", line 965, in async_execute_cell
    await self._check_raise_for_error(cell, cell_index, exec_reply)
  File "/home/runner/.local/lib/python3.10/site-packages/nbclient/client.py", line 862, in _check_raise_for_error
    raise CellExecutionError.from_cell_and_msg(cell, exec_reply_content)
nbclient.exceptions.CellExecutionError: An error occurred while executing the following cell:
------------------
print(f"N = {dataset.data.count_pieces()} annotated pieces, {dataset.data.count_parsed_tsvs()} parsed dataframes.")
------------------

[0;31m---------------------------------------------------------------------------[0m
[0;31mAttributeError[0m                            Traceback (most recent call last)
Cell [0;32mIn[6], line 1[0m
[0;32m----> 1[0m [38;5;28mprint[39m([38;5;124mf[39m[38;5;124m"[39m[38;5;124mN = [39m[38;5;132;01m{[39;00m[43mdataset[49m[38;5;241;43m.[39;49m[43mdata[49m[38;5;241;43m.[39;49m[43mcount_pieces[49m()[38;5;132;01m}[39;00m[38;5;124m annotated pieces, [39m[38;5;132;01m{[39;00mdataset[38;5;241m.[39mdata[38;5;241m.[39mcount_parsed_tsvs()[38;5;132;01m}[39;00m[38;5;124m parsed dataframes.[39m[38;5;124m"[39m)

File [0;32m~/.local/lib/python3.10/site-packages/ms3/parse.py:1316[0m, in [0;36mParse.__getattr__[0;34m(self, view_name)[0m
[1;32m   1314[0m     [38;5;28;01mreturn[39;00m [38;5;28mself[39m
[1;32m   1315[0m [38;5;28;01melse[39;00m:
[0;32m-> 1316[0m     [38;5;28;01mraise[39;00m [38;5;167;01mAttributeError[39;00m([38;5;124mf[39m[38;5;124m"[39m[38;5;124m'[39m[38;5;132;01m{[39;00mview_name[38;5;132;01m}[39;00m[38;5;124m'[39m[38;5;124m is not an existing view. Use _.get_view([39m[38;5;124m'[39m[38;5;132;01m{[39;00mview_name[38;5;132;01m}[39;00m[38;5;124m'[39m[38;5;124m) to create it.[39m[38;5;124m"[39m)

[0;31mAttributeError[0m: 'count_pieces' is not an existing view. Use _.get_view('count_pieces') to create it.
AttributeError: 'count_pieces' is not an existing view. Use _.get_view('count_pieces') to create it.

